Workbook

Sheet PROJECT INSTRUCTIONS
C1: PR. 1 Fundamental Booster
C2: Topics: - Relative & Absolute References, Formatting, Data Input - IF Formulas, Nested IFs, IF with AND/OR - COUNTIFS, SUMIFS, AVERAGEIFS - Lookup Functions (VLOOKUP, XLOOKUP, XMATCH) - INDEX/MATCH for dynamic searches - TEXT Functions for string manipulations - INDIRECT and OFFSET for dynamic references - Date/Time, Math Functions, FILTER function Main Tasks: 1. Apply IF formulas to classify student grades. 2. Use COUNTIFS to count students scoring above 60. 3. Use VLOOKUP to find a product price from sales data. 4. Apply XLOOKUP to fetch employee salaries dynamically. 5. Format and analyze date of joining in Employee data. 6. Use FILTER function to extract students with grades above 80. Deliverable: Complete the given worksheets by applying the required formulas in respective sheets.
C5: Essential Tasks
C6: Relative & Absolute Cell References, Formatting, and Data Input
C7: Enter and format data (bold, italic, currency, date, custom formats).
A8: Use absolute ($A$1) and relative (A1) references in formulas. | C8: Use absolute ($A$1) and relative (A1) references in formulas.
A10: Using IF Formula & Nesting IF Formulas | C10: Using IF Formula & Nesting IF Formulas
A11: Classify students' grades based on their scores. | C11: Classify students' grades based on their scores.
C12: Compute discounts for sales based on price thresholds.
C14: Using IF with AND/OR Formulas
C15: Identify students who scored above 80 in both Math & Science using IF(AND(...)).
C16: Determine whether a product is eligible for discount using IF(OR(...)).
C18: COUNTIFS, SUMIFS, AVERAGEIFS
C19: Count the number of students who scored above 50 in Math.
C20: Sum total sales for a specific region and product.
C21: Calculate the average score for students who scored above 60.
C23: VLOOKUP Function
C24: Fetch student names based on ID from a separate dataset.
C25: Retrieve product prices based on product codes.
C27: INDEX and MATCH Functions
... C56: Extract a list of top-performing students based on scores.

Sheet STUDENTS GRADE
A1: Student ID | B1: Name | C1: Math | D1: Science | E1: English | F1: Enrollment Date | G1: AVERAGE | H1: GRADE
A2: 1001 | B2: Student 1 | C2: 61 | D2: 48 | E2: 76 | F2: 43101 | G2: =AVERAGE('STUDENTS GRADE'!$C2,'STUDENTS GRADE'!$D2,'STUDENTS GRADE'!$E2) -> 61.666667 | H2: =IF(G2>80,"A", IF(G2>70,"B",IF(G2>60,"C",IF(G2>50,"D","FAIL")))) -> C | K2: STUDENTS WHO SCORED ABOVE 60 IN MATH
A3: 1002 | B3: Student 2 | C3: 78 | D3: 76 | E3: 70 | F3: 43281 | G3: =AVERAGE('STUDENTS GRADE'!$C3,'STUDENTS GRADE'!$D3,'STUDENTS GRADE'!$E3) -> 74.666667 | H3: =IF(G3>80,"A", IF(G3>70,"B",IF(G3>60,"C",IF(G3>50,"D","FAIL")))) -> B | K3: =COUNTIFS(C2:C21,">60") -> 19
A4: 1003 | B4: Student 3 | C4: 97 | D4: 60 | E4: 51 | F4: 43461 | G4: =AVERAGE('STUDENTS GRADE'!$C4,'STUDENTS GRADE'!$D4,'STUDENTS GRADE'!$E4) -> 69.333333 | H4: =IF(G4>80,"A", IF(G4>70,"B",IF(G4>60,"C",IF(G4>50,"D","FAIL")))) -> C
A5: 1004 | B5: Student 4 | C5: 74 | D5: 55 | E5: 46 | F5: 43641 | G5: =AVERAGE('STUDENTS GRADE'!$C5,'STUDENTS GRADE'!$D5,'STUDENTS GRADE'!$E5) -> 58.333333 | H5: =IF(G5>80,"A", IF(G5>70,"B",IF(G5>60,"C",IF(G5>50,"D","FAIL")))) -> D
A6: 1005 | B6: Student 5 | C6: 68 | D6: 74 | E6: 84 | F6: 43821 | G6: =AVERAGE('STUDENTS GRADE'!$C6,'STUDENTS GRADE'!$D6,'STUDENTS GRADE'!$E6) -> 75.333333 | H6: =IF(G6>80,"A", IF(G6>70,"B",IF(G6>60,"C",IF(G6>50,"D","FAIL")))) -> B | K6: STUDENTS WHO SCORED ABOVED 60 IN ENGLISH | N6: ED 60 IN | O6: SCIENCE
A7: 1006 | B7: Student 6 | C7: 80 | D7: 70 | E7: 65 | F7: 44001 | G7: =AVERAGE('STUDENTS GRADE'!$C7,'STUDENTS GRADE'!$D7,'STUDENTS GRADE'!$E7) -> 71.666667 | H7: =IF(G7>80,"A", IF(G7>70,"B",IF(G7>60,"C",IF(G7>50,"D","FAIL")))) -> B | K7: =COUNTIFS(D2:D21,">60") -> 11
A8: 1007 | B8: Student 7 | C8: 75 | D8: 47 | E8: 78 | F8: 44181 | G8: =AVERAGE('STUDENTS GRADE'!$C8,'STUDENTS GRADE'!$D8,'STUDENTS GRADE'!$E8) -> 66.666667 | H8: =IF(G8>80,"A", IF(G8>70,"B",IF(G8>60,"C",IF(G8>50,"D","FAIL")))) -> C
A9: 1008 | B9: Student 8 | C9: 94 | D9: 67 | E9: 64 | F9: 44361 | G9: =AVERAGE('STUDENTS GRADE'!$C9,'STUDENTS GRADE'!$D9,'STUDENTS GRADE'!$E9) -> 75 | H9: =IF(G9>80,"A", IF(G9>70,"B",IF(G9>60,"C",IF(G9>50,"D","FAIL")))) -> B | K9: STUDENTS WHO SCORED ABOVE 60 IN ENGLISH
A10: 1009 | B10: Student 9 | C10: 41 | D10: 75 | E10: 56 | F10: 44541 | G10: =AVERAGE('STUDENTS GRADE'!$C10,'STUDENTS GRADE'!$D10,'STUDENTS GRADE'!$E10) -> 57.333333 | H10: =IF(G10>80,"A", IF(G10>70,"B",IF(G10>60,"C",IF(G10>50,"D","FAIL")))) -> D | K10: =COUNTIFS(E2:E21,">60") -> 10
A11: 1010 | B11: Student 10 | C11: 98 | D11: 54 | E11: 58 | F11: 44721 | G11: =AVERAGE('STUDENTS GRADE'!$C11,'STUDENTS GRADE'!$D11,'STUDENTS GRADE'!$E11) -> 70 | H11: =IF(G11>80,"A", IF(G11>70,"B",IF(G11>60,"C",IF(G11>50,"D","FAIL")))) -> C
A12: 1011 | B12: Student 11 | C12: 73 | D12: 79 | E12: 53 | F12: 44901 | G12: =AVERAGE('STUDENTS GRADE'!$C12,'STUDENTS GRADE'!$D12,'STUDENTS GRADE'!$E12) -> 68.333333 | H12: =IF(G12>80,"A", IF(G12>70,"B",IF(G12>60,"C",IF(G12>50,"D","FAIL")))) -> C
A13: 1012 | B13: Student 12 | C13: 85 | D13: 89 | E13: 79 | F13: 45081 | G13: =AVERAGE('STUDENTS GRADE'!$C13,'STUDENTS GRADE'!$D13,'STUDENTS GRADE'!$E13) -> 84.333333 | H13: =IF(G13>80,"A", IF(G13>70,"B",IF(G13>60,"C",IF(G13>50,"D","FAIL")))) -> A
A14: 1013 | B14: Student 13 | C14: 98 | D14: 90 | E14: 97 | F14: 45261 | G14: =AVERAGE('STUDENTS GRADE'!$C14,'STUDENTS GRADE'!$D14,'STUDENTS GRADE'!$E14) -> 95 | H14: =IF(G14>80,"A", IF(G14>70,"B",IF(G14>60,"C",IF(G14>50,"D","FAIL")))) -> A
A15: 1014 | B15: Student 14 | C15: 93 | D15: 40 | E15: 44 | F15: 45441 | G15: =AVERAGE('STUDENTS GRADE'!$C15,'STUDENTS GRADE'!$D15,'STUDENTS GRADE'!$E15) -> 59 | H15: =IF(G15>80,"A", IF(G15>70,"B",IF(G15>60,"C",IF(G15>50,"D","FAIL")))) -> D
A16: 1015 | B16: Student 15 | C16: 70 | D16: 51 | E16: 75 | F16: 45621 | G16: =AVERAGE('STUDENTS GRADE'!$C16,'STUDENTS GRADE'!$D16,'STUDENTS GRADE'!$E16) -> 65.333333 | H16: =IF(G16>80,"A", IF(G16>70,"B",IF(G16>60,"C",IF(G16>50,"D","FAIL")))) -> C
A17: 1016 | B17: Student 16 | C17: 98 | D17: 77 | E17: 60 | F17: 45801 | G17: =AVERAGE('STUDENTS GRADE'!$C17,'STUDENTS GRADE'!$D17,'STUDENTS GRADE'!$E17) -> 78.333333 | H17: =IF(G17>80,"A", IF(G17>70,"B",IF(G17>60,"C",IF(G17>50,"D","FAIL")))) -> B
A18: 1017 | B18: Student 17 | C18: 66 | D18: 59 | E18: 40 | F18: 45981 | G18: =AVERAGE('STUDENTS GRADE'!$C18,'STUDENTS GRADE'!$D18,'STUDENTS GRADE'!$E18) -> 55 | H18: =IF(G18>80,"A", IF(G18>70,"B",IF(G18>60,"C",IF(G18>50,"D","FAIL")))) -> D
A19: 1018 | B19: Student 18 | C19: 82 | D19: 48 | E19: 79 | F19: 46161 | G19: =AVERAGE('STUDENTS GRADE'!$C19,'STUDENTS GRADE'!$D19,'STUDENTS GRADE'!$E19) -> 69.666667 | H19: =IF(G19>80,"A", IF(G19>70,"B",IF(G19>60,"C",IF(G19>50,"D","FAIL")))) -> C
A20: 1019 | B20: Student 19 | C20: 90 | D20: 78 | E20: 60 | F20: 46341 | G20: =AVERAGE('STUDENTS GRADE'!$C20,'STUDENTS GRADE'!$D20,'STUDENTS GRADE'!$E20) -> 76 | H20: =IF(G20>80,"A", IF(G20>70,"B",IF(G20>60,"C",IF(G20>50,"D","FAIL")))) -> B
A21: 1020 | B21: Student 20 | C21: 83 | D21: 92 | E21: 55 | F21: 46521 | G21: =AVERAGE('STUDENTS GRADE'!$C21,'STUDENTS GRADE'!$D21,'STUDENTS GRADE'!$E21) -> 76.666667 | H21: =IF(G21>80,"A", IF(G21>70,"B",IF(G21>60,"C",IF(G21>50,"D","FAIL")))) -> B

Sheet SALES DATA
A1: Sales ID | B1: Product | C1: Region | D1: Salesperson | E1: Amount | F1: Date | G1: THRESHOLD DISCOUNT | H1: FINAL PRICE | I1: PRODUCT CODE | J1: MONTH
A2: 2001 | B2: Keyboard | C2: South | D2: Person 1 | E2: 7048 | F2: 44927 | G2: =IF(E2<5000,5%,IF(E2<20000,10%,IF(E2<30000,15%,20%))) -> 0.1 | H2: =E2-(E2*G2) -> 6343.2 | I2: =IF(B2="KEYBOARD",1001,IF(B2="PRINTER",1002,IF(B2="MOUSE",1003,IF(B2="LAPTOP",1004,IF(B2="MONITOR",1005))))) -> 1001 | J2: =MONTH('SALES DATA'!$F2) -> 1
A3: 2002 | B3: Printer | C3: West | D3: Person 2 | E3: 17428 | F3: 44942 | G3: =IF(E3<5000,5%,IF(E3<20000,10%,IF(E3<30000,15%,20%))) -> 0.1 | H3: =E3-(E3*G3) -> 15685.2 | I3: =IF(B3="KEYBOARD",1001,IF(B3="PRINTER",1002,IF(B3="MOUSE",1003,IF(B3="LAPTOP",1004,IF(B3="MONITOR",1005))))) -> 1002 | J3: =MONTH('SALES DATA'!$F3) -> 1
A4: 2003 | B4: Mouse | C4: South | D4: Person 3 | E4: 23672 | F4: 44957 | G4: =IF(E4<5000,5%,IF(E4<20000,10%,IF(E4<30000,15%,20%))) -> 0.15 | H4: =E4-(E4*G4) -> 20121.2 | I4: =IF(B4="KEYBOARD",1001,IF(B4="PRINTER",1002,IF(B4="MOUSE",1003,IF(B4="LAPTOP",1004,IF(B4="MONITOR",1005))))) -> 1003 | J4: =MONTH('SALES DATA'!$F4) -> 1 | M4: SUM OF TOTAL SALES OF LAPTOPN IN WEST REGION
A5: 2004 | B5: Printer | C5: East | D5: Person 4 | E5: 5264 | F5: 44972 | G5: =IF(E5<5000,5%,IF(E5<20000,10%,IF(E5<30000,15%,20%))) -> 0.1 | H5: =E5-(E5*G5) -> 4737.6 | I5: =IF(B5="KEYBOARD",1001,IF(B5="PRINTER",1002,IF(B5="MOUSE",1003,IF(B5="LAPTOP",1004,IF(B5="MONITOR",1005))))) -> 1002 | J5: =MONTH('SALES DATA'!$F5) -> 2 | M5: =SUMIFS(E2:E21,C2:C21,"EAST",B2:B21,"LAPTOP") -> 31238
A6: 2005 | B6: Keyboard | C6: North | D6: Person 5 | E6: 43388 | F6: 44987 | G6: =IF(E6<5000,5%,IF(E6<20000,10%,IF(E6<30000,15%,20%))) -> 0.2 | H6: =E6-(E6*G6) -> 34710.4 | I6: =IF(B6="KEYBOARD",1001,IF(B6="PRINTER",1002,IF(B6="MOUSE",1003,IF(B6="LAPTOP",1004,IF(B6="MONITOR",1005))))) -> 1001 | J6: =MONTH('SALES DATA'!$F6) -> 3
A7: 2006 | B7: Mouse | C7: North | D7: Person 6 | E7: 19757 | F7: 45002 | G7: =IF(E7<5000,5%,IF(E7<20000,10%,IF(E7<30000,15%,20%))) -> 0.1 | H7: =E7-(E7*G7) -> 17781.3 | I7: =IF(B7="KEYBOARD",1001,IF(B7="PRINTER",1002,IF(B7="MOUSE",1003,IF(B7="LAPTOP",1004,IF(B7="MONITOR",1005))))) -> 1003 | J7: =MONTH('SALES DATA'!$F7) -> 3
A8: 2007 | B8: Mouse | C8: East | D8: Person 7 | E8: 32058 | F8: 45017 | G8: =IF(E8<5000,5%,IF(E8<20000,10%,IF(E8<30000,15%,20%))) -> 0.2 | H8: =E8-(E8*G8) -> 25646.4 | I8: =IF(B8="KEYBOARD",1001,IF(B8="PRINTER",1002,IF(B8="MOUSE",1003,IF(B8="LAPTOP",1004,IF(B8="MONITOR",1005))))) -> 1003 | J8: =MONTH('SALES DATA'!$F8) -> 4
A9: 2008 | B9: Keyboard | C9: East | D9: Person 8 | E9: 46429 | F9: 45032 | G9: =IF(E9<5000,5%,IF(E9<20000,10%,IF(E9<30000,15%,20%))) -> 0.2 | H9: =E9-(E9*G9) -> 37143.2 | I9: =IF(B9="KEYBOARD",1001,IF(B9="PRINTER",1002,IF(B9="MOUSE",1003,IF(B9="LAPTOP",1004,IF(B9="MONITOR",1005))))) -> 1001 | J9: =MONTH('SALES DATA'!$F9) -> 4
A10: 2009 | B10: Printer | C10: East | D10: Person 9 | E10: 19746 | F10: 45047 | G10: =IF(E10<5000,5%,IF(E10<20000,10%,IF(E10<30000,15%,20%))) -> 0.1 | H10: =E10-(E10*G10) -> 17771.4 | I10: =IF(B10="KEYBOARD",1001,IF(B10="PRINTER",1002,IF(B10="MOUSE",1003,IF(B10="LAPTOP",1004,IF(B10="MONITOR",1005))))) -> 1002 | J10: =MONTH('SALES DATA'!$F10) -> 5
A11: 2010 | B11: Keyboard | C11: South | D11: Person 10 | E11: 35185 | F11: 45062 | G11: =IF(E11<5000,5%,IF(E11<20000,10%,IF(E11<30000,15%,20%))) -> 0.2 | H11: =E11-(E11*G11) -> 28148 | I11: =IF(B11="KEYBOARD",1001,IF(B11="PRINTER",1002,IF(B11="MOUSE",1003,IF(B11="LAPTOP",1004,IF(B11="MONITOR",1005))))) -> 1001 | J11: =MONTH('SALES DATA'!$F11) -> 5
A12: 2011 | B12: Keyboard | C12: East | D12: Person 11 | E12: 33920 | F12: 45077 | G12: =IF(E12<5000,5%,IF(E12<20000,10%,IF(E12<30000,15%,20%))) -> 0.2 | H12: =E12-(E12*G12) -> 27136 | I12: =IF(B12="KEYBOARD",1001,IF(B12="PRINTER",1002,IF(B12="MOUSE",1003,IF(B12="LAPTOP",1004,IF(B12="MONITOR",1005))))) -> 1001 | J12: =MONTH('SALES DATA'!$F12) -> 5
A13: 2012 | B13: Monitor | C13: North | D13: Person 12 | E13: 35611 | F13: 45092 | G13: =IF(E13<5000,5%,IF(E13<20000,10%,IF(E13<30000,15%,20%))) -> 0.2 | H13: =E13-(E13*G13) -> 28488.8 | I13: =IF(B13="KEYBOARD",1001,IF(B13="PRINTER",1002,IF(B13="MOUSE",1003,IF(B13="LAPTOP",1004,IF(B13="MONITOR",1005))))) -> 1005 | J13: =MONTH('SALES DATA'!$F13) -> 6
A14: 2013 | B14: Laptop | C14: East | D14: Person 13 | E14: 15560 | F14: 45107 | G14: =IF(E14<5000,5%,IF(E14<20000,10%,IF(E14<30000,15%,20%))) -> 0.1 | H14: =E14-(E14*G14) -> 14004 | I14: =IF(B14="KEYBOARD",1001,IF(B14="PRINTER",1002,IF(B14="MOUSE",1003,IF(B14="LAPTOP",1004,IF(B14="MONITOR",1005))))) -> 1004 | J14: =MONTH('SALES DATA'!$F14) -> 6
A15: 2014 | B15: Laptop | C15: South | D15: Person 14 | E15: 7283 | F15: 45122 | G15: =IF(E15<5000,5%,IF(E15<20000,10%,IF(E15<30000,15%,20%))) -> 0.1 | H15: =E15-(E15*G15) -> 6554.7 | I15: =IF(B15="KEYBOARD",1001,IF(B15="PRINTER",1002,IF(B15="MOUSE",1003,IF(B15="LAPTOP",1004,IF(B15="MONITOR",1005))))) -> 1004 | J15: =MONTH('SALES DATA'!$F15) -> 7
A16: 2015 | B16: Laptop | C16: East | D16: Person 15 | E16: 15678 | F16: 45137 | G16: =IF(E16<5000,5%,IF(E16<20000,10%,IF(E16<30000,15%,20%))) -> 0.1 | H16: =E16-(E16*G16) -> 14110.2 | I16: =IF(B16="KEYBOARD",1001,IF(B16="PRINTER",1002,IF(B16="MOUSE",1003,IF(B16="LAPTOP",1004,IF(B16="MONITOR",1005))))) -> 1004 | J16: =MONTH('SALES DATA'!$F16) -> 7
A17: 2016 | B17: Mouse | C17: East | D17: Person 16 | E17: 5277 | F17: 45152 | G17: =IF(E17<5000,5%,IF(E17<20000,10%,IF(E17<30000,15%,20%))) -> 0.1 | H17: =E17-(E17*G17) -> 4749.3 | I17: =IF(B17="KEYBOARD",1001,IF(B17="PRINTER",1002,IF(B17="MOUSE",1003,IF(B17="LAPTOP",1004,IF(B17="MONITOR",1005))))) -> 1003 | J17: =MONTH('SALES DATA'!$F17) -> 8
... A21: 2020 | B21: Printer | C21: West | D21: Person 20 | E21: 33953 | F21: 45212 | G21: =IF(E21<5000,5%,IF(E21<20000,10%,IF(E21<30000,15%,20%))) -> 0.2 | H21: =E21-(E21*G21) -> 27162.4 | I21: =IF(B21="KEYBOARD",1001,IF(B21="PRINTER",1002,IF(B21="MOUSE",1003,IF(B21="LAPTOP",1004,IF(B21="MONITOR",1005))))) -> 1002 | J21: =MONTH('SALES DATA'!$F21) -> 10

Sheet EMPLOYEE DATA
A1: Employee ID | B1: Name | C1: Department | D1: Salary | E1: Joining Date | F1: joining month
A2: 3001 | B2: Employee 1 | C2: Finance | D2: 86766 | E2: 42005 | F2: =TEXT(E2,"mmmm") -> January
A3: 3002 | B3: Employee 2 | C3: Finance | D3: 31943 | E3: 42255 | F3: =TEXT(E3,"mmmm") -> September
A4: 3003 | B4: Employee 3 | C4: HR | D4: 63374 | E4: 42505 | F4: =TEXT(E4,"mmmm") -> May
A5: 3004 | B5: Employee 4 | C5: Finance | D5: 109972 | E5: 42755 | F5: =TEXT(E5,"mmmm") -> January
A6: 3005 | B6: Employee 5 | C6: IT | D6: 54149 | E6: 43005 | F6: =TEXT(E6,"mmmm") -> September
A7: 3006 | B7: Employee 6 | C7: IT | D7: 78689 | E7: 43255 | F7: =TEXT(E7,"mmmm") -> June
A8: 3007 | B8: Employee 7 | C8: Marketing | D8: 35960 | E8: 43505 | F8: =TEXT(E8,"mmmm") -> February
A9: 3008 | B9: Employee 8 | C9: IT | D9: 91659 | E9: 43755 | F9: =TEXT(E9,"mmmm") -> October
A10: 3009 | B10: Employee 9 | C10: IT | D10: 90423 | E10: 44005 | F10: =TEXT(E10,"mmmm") -> June
A11: 3010 | B11: Employee 10 | C11: HR | D11: 107877 | E11: 44255 | F11: =TEXT(E11,"mmmm") -> February
A12: 3011 | B12: Employee 11 | C12: Finance | D12: 107634 | E12: 44505 | F12: =TEXT(E12,"mmmm") -> November
A13: 3012 | B13: Employee 12 | C13: Finance | D13: 35226 | E13: 44755 | F13: =TEXT(E13,"mmmm") -> July
... A21: 3020 | B21: Employee 20 | C21: Marketing | D21: 99924 | E21: 46755 | F21: =TEXT(E21,"mmmm") -> January

Sheet ANSWER SHEET
A1: 15 | B1: STUDENT ABOVE 80 IN MATH &SCIENCE | D1: 16 | E1: IF+OR | G1: 19 | H1: COUNTIF STUDENT WHO SCORED MORE THAN 50 IN MATH | J1: 53 | K1: MATH FUNCTION USE ROUND()
B2: =IF(AND('STUDENTS GRADE'!C2>80,'STUDENTS GRADE'!D2>80),"QUALIFIED","NOT QUALIFIED") -> NOT QUALIFIED | E2: =IF(OR('SALES DATA'!E2>20000,),"ELIGIBLE","NOT ELIGIBLE") -> NOT ELIGIBLE | H2: =COUNTIFS('STUDENTS GRADE'!C:C,">50") -> 19 | K2: =ROUND('NEW TABLE'!D2,2) -> 50164.45 | M2: 37 | N2: XLOOKUP FIND EMPLOYEES SALARIES WITHOUT WORRIED ABOUT SORTED DATA
B3: =IF(AND('STUDENTS GRADE'!C3>80,'STUDENTS GRADE'!D3>80),"QUALIFIED","NOT QUALIFIED") -> NOT QUALIFIED | E3: =IF(OR('SALES DATA'!E3>20000,),"ELIGIBLE","NOT ELIGIBLE") -> NOT ELIGIBLE | K3: =ROUND('NEW TABLE'!D3,2) -> 45846.65 | N3: EMPLOYEE ID | O3: SALARY
B4: =IF(AND('STUDENTS GRADE'!C4>80,'STUDENTS GRADE'!D4>80),"QUALIFIED","NOT QUALIFIED") -> NOT QUALIFIED | E4: =IF(OR('SALES DATA'!E4>20000,),"ELIGIBLE","NOT ELIGIBLE") -> ELIGIBLE | K4: =ROUND('NEW TABLE'!D4,2) -> 49527.54 | N4: 3010 | O4: =_xlfn.XLOOKUP(N4,'EMPLOYEE DATA'!$A$2:$A$21,'EMPLOYEE DATA'!$D$2:$D$21,("NO FOUND")) -> 107877
B5: =IF(AND('STUDENTS GRADE'!C5>80,'STUDENTS GRADE'!D5>80),"QUALIFIED","NOT QUALIFIED") -> NOT QUALIFIED | E5: =IF(OR('SALES DATA'!E5>20000,),"ELIGIBLE","NOT ELIGIBLE") -> NOT ELIGIBLE | G5: 20 | H5: TOTAL SALES OF LAPTOP IN EAST REGION | K5: =ROUND('NEW TABLE'!D5,2) -> 46072.25
B6: =IF(AND('STUDENTS GRADE'!C6>80,'STUDENTS GRADE'!D6>80),"QUALIFIED","NOT QUALIFIED") -> NOT QUALIFIED | E6: =IF(OR('SALES DATA'!E6>20000,),"ELIGIBLE","NOT ELIGIBLE") -> ELIGIBLE | H6: =SUMIFS('SALES DATA'!E2:E21,'SALES DATA'!C2:C21,"EAST",'SALES DATA'!B2:B21,"LAPTOP") -> 31238 | K6: =ROUND('NEW TABLE'!D6,2) -> 54451.46
B7: =IF(AND('STUDENTS GRADE'!C7>80,'STUDENTS GRADE'!D7>80),"QUALIFIED","NOT QUALIFIED") -> NOT QUALIFIED | E7: =IF(OR('SALES DATA'!E7>20000,),"ELIGIBLE","NOT ELIGIBLE") -> NOT ELIGIBLE | M7: 36 | N7: XLOOKUP SEARCH FOR SLESPERSON PERFORMANCE BASED O FLEXIBLE SEARCH CRITERIA
B8: =IF(AND('STUDENTS GRADE'!C8>80,'STUDENTS GRADE'!D8>80),"QUALIFIED","NOT QUALIFIED") -> NOT QUALIFIED | E8: =IF(OR('SALES DATA'!E8>20000,),"ELIGIBLE","NOT ELIGIBLE") -> ELIGIBLE | O8: =_xlfn.XLOOKUP('SALES DATA'!D15,'SALES DATA'!D2:D21,'SALES DATA'!E2:E21,"Not Found") -> 7283
B9: =IF(AND('STUDENTS GRADE'!C9>80,'STUDENTS GRADE'!D9>80),"QUALIFIED","NOT QUALIFIED") -> NOT QUALIFIED | E9: =IF(OR('SALES DATA'!E9>20000,),"ELIGIBLE","NOT ELIGIBLE") -> ELIGIBLE
B10: =IF(AND('STUDENTS GRADE'!C10>80,'STUDENTS GRADE'!D10>80),"QUALIFIED","NOT QUALIFIED") -> NOT QUALIFIED | E10: =IF(OR('SALES DATA'!E10>20000,),"ELIGIBLE","NOT ELIGIBLE") -> NOT ELIGIBLE | J10: 53 | K10: MATH FUNCTION USE CELING()
B11: =IF(AND('STUDENTS GRADE'!C11>80,'STUDENTS GRADE'!D11>80),"QUALIFIED","NOT QUALIFIED") -> NOT QUALIFIED | E11: =IF(OR('SALES DATA'!E11>20000,),"ELIGIBLE","NOT ELIGIBLE") -> ELIGIBLE | G11: 21 | H11: AVERAGEIFS IN MATH 60ABOVE | K11: =CEILING('NEW TABLE'!D2,100) -> 50200
B12: =IF(AND('STUDENTS GRADE'!C12>80,'STUDENTS GRADE'!D12>80),"QUALIFIED","NOT QUALIFIED") -> NOT QUALIFIED | E12: =IF(OR('SALES DATA'!E12>20000,),"ELIGIBLE","NOT ELIGIBLE") -> ELIGIBLE | H12: =AVERAGEIFS('STUDENTS GRADE'!C:C,'STUDENTS GRADE'!C:C,">60") -> 82.263158 | K12: =CEILING('NEW TABLE'!D3,100) -> 45900
B13: =IF(AND('STUDENTS GRADE'!C13>80,'STUDENTS GRADE'!D13>80),"QUALIFIED","NOT QUALIFIED") -> QUALIFIED | E13: =IF(OR('SALES DATA'!E13>20000,),"ELIGIBLE","NOT ELIGIBLE") -> ELIGIBLE | H13: AVERAGEIFS IN SCIENCE 60ABOVE | K13: =CEILING('NEW TABLE'!D4,100) -> 49600 | M13: 32 | N13: TEXT FUNCTION EXTRACT FIRST NAMES FROM FULL NAMES USING LEFT AND FIND
B14: =IF(AND('STUDENTS GRADE'!C14>80,'STUDENTS GRADE'!D14>80),"QUALIFIED","NOT QUALIFIED") -> QUALIFIED | E14: =IF(OR('SALES DATA'!E14>20000,),"ELIGIBLE","NOT ELIGIBLE") -> NOT ELIGIBLE | H14: =AVERAGEIFS('STUDENTS GRADE'!D:D,'STUDENTS GRADE'!D:D,">60") -> 78.818182 | K14: =CEILING('NEW TABLE'!D5,100) -> 46100 | N14: =LEFT('NEW TABLE'!B2,FIND(" ",'NEW TABLE'!B2)-1) -> Harsh
B15: =IF(AND('STUDENTS GRADE'!C15>80,'STUDENTS GRADE'!D15>80),"QUALIFIED","NOT QUALIFIED") -> NOT QUALIFIED | E15: =IF(OR('SALES DATA'!E15>20000,),"ELIGIBLE","NOT ELIGIBLE") -> NOT ELIGIBLE | H15: AVERAGEIFS IN ENGLISH 60 ABOVE | K15: =CEILING('NEW TABLE'!D6,100) -> 54500 | N15: =LEFT('NEW TABLE'!B3,FIND(" ",'NEW TABLE'!B3)-1) -> Kunj
B16: =IF(AND('STUDENTS GRADE'!C16>80,'STUDENTS GRADE'!D16>80),"QUALIFIED","NOT QUALIFIED") -> NOT QUALIFIED | E16: =IF(OR('SALES DATA'!E16>20000,),"ELIGIBLE","NOT ELIGIBLE") -> NOT ELIGIBLE | H16: =AVERAGEIFS('STUDENTS GRADE'!E:E,'STUDENTS GRADE'!E:E,">60") -> 76.7 | N16: =LEFT('NEW TABLE'!B4,FIND(" ",'NEW TABLE'!B4)-1) -> Ahmed
B17: =IF(AND('STUDENTS GRADE'!C17>80,'STUDENTS GRADE'!D17>80),"QUALIFIED","NOT QUALIFIED") -> NOT QUALIFIED | E17: =IF(OR('SALES DATA'!E17>20000,),"ELIGIBLE","NOT ELIGIBLE") -> NOT ELIGIBLE | N17: =LEFT('NEW TABLE'!B5,FIND(" ",'NEW TABLE'!B5)-1) -> Shrey
B18: =IF(AND('STUDENTS GRADE'!C18>80,'STUDENTS GRADE'!D18>80),"QUALIFIED","NOT QUALIFIED") -> NOT QUALIFIED | E18: =IF(OR('SALES DATA'!E18>20000,),"ELIGIBLE","NOT ELIGIBLE") -> ELIGIBLE | J18: 53 | K18: MATH FUNCTION USE FLOOR() | N18: =LEFT('NEW TABLE'!B6,FIND(" ",'NEW TABLE'!B6)-1) -> SAHIL
B19: =IF(AND('STUDENTS GRADE'!C19>80,'STUDENTS GRADE'!D19>80),"QUALIFIED","NOT QUALIFIED") -> NOT QUALIFIED | E19: =IF(OR('SALES DATA'!E19>20000,),"ELIGIBLE","NOT ELIGIBLE") -> ELIGIBLE | G19: 24 | H19: VLOOKUP FETCH NAMES FROM ID | K19: =FLOOR('NEW TABLE'!D2,100) -> 50100
B20: =IF(AND('STUDENTS GRADE'!C20>80,'STUDENTS GRADE'!D20>80),"QUALIFIED","NOT QUALIFIED") -> NOT QUALIFIED | E20: =IF(OR('SALES DATA'!E20>20000,),"ELIGIBLE","NOT ELIGIBLE") -> ELIGIBLE | H20: =VLOOKUP('STUDENTS GRADE'!A5,'STUDENTS GRADE'!A:G,2,FALSE) -> Student 4 | K20: =FLOOR('NEW TABLE'!D3,100) -> 45800 | M20: 33 | N20: TEXT UPPER FUNCTION | Q20: 33 TEXT LOWER FUNCTION
B21: =IF(AND('STUDENTS GRADE'!C21>80,'STUDENTS GRADE'!D21>80),"QUALIFIED","NOT QUALIFIED") -> QUALIFIED | E21: =IF(OR('SALES DATA'!E21>20000,),"ELIGIBLE","NOT ELIGIBLE") -> ELIGIBLE | K21: =FLOOR('NEW TABLE'!D4,100) -> 49500 | N21: =UPPER(N14) -> HARSH | Q21: =LOWER(N21) -> harsh
G22: 25 | H22: VLOOKUP PRODUCT PRICE BASED ON PRODUCT CODE | K22: =FLOOR('NEW TABLE'!D5,100) -> 46000 | N22: =UPPER(N15) -> KUNJ | Q22: =LOWER(N22) -> kunj
H23: =VLOOKUP('SALES DATA'!A4,'SALES DATA'!A:F,5,FALSE) -> 23672 | K23: =FLOOR('NEW TABLE'!D6,100) -> 54400 | N23: =UPPER(N16) -> AHMED | Q23: =LOWER(N23) -> ahmed
N24: =UPPER(N17) -> SHREY | Q24: =LOWER(N24) -> shrey
N25: =UPPER(N18) -> SAHIL | Q25: =LOWER(N25) -> sahil
A26: 28 | B26: INDEX AND MATCH SALES VALUE FOR SPECIFIC SALES PERSON FOR SPECIFIC MONTH
B27: =INDEX('EMPLOYEE DATA'!D2:D21,MATCH('EMPLOYEE DATA'!A5,'EMPLOYEE DATA'!A2:A21,0)) -> 109972 | G27: 29 | H27: INDEX AND MATCH EMPLOYEE SALARIES WITHOUT WORRING ABOUT SORTED DATA
H28: =INDEX('EMPLOYEE DATA'!D:D,MATCH('EMPLOYEE DATA'!G2,'EMPLOYEE DATA'!A:A,0)) -> #N/A
G30: 40 | H30: XMATCH FIND THE POSITION OF A PRODUCT IN SALES LIST
A31: 6 | B31: ABSOLUTE REFERENCE | C31: RELATIVE REFERENCE | H31: =_xlfn.XMATCH("LAPTOP",'SALES DATA'!B2:B21,0) -> 13
B32: =SUM('STUDENTS GRADE'!$C$2+'STUDENTS GRADE'!E2) -> 137 | C32: =AVERAGE('STUDENTS GRADE'!C2,'STUDENTS GRADE'!D2,'STUDENTS GRADE'!E2) -> 61.666667
B33: =SUM('STUDENTS GRADE'!$C$2+'STUDENTS GRADE'!E3) -> 131 | C33: =AVERAGE('STUDENTS GRADE'!C3,'STUDENTS GRADE'!D3,'STUDENTS GRADE'!E3) -> 74.666667
B34: =SUM('STUDENTS GRADE'!$C$2+'STUDENTS GRADE'!E4) -> 112 | C34: =AVERAGE('STUDENTS GRADE'!C4,'STUDENTS GRADE'!D4,'STUDENTS GRADE'!E4) -> 69.333333 | G34: 43 | H34: INDIRECT FUNCTION
B35: =SUM('STUDENTS GRADE'!$C$2+'STUDENTS GRADE'!E5) -> 107 | C35: =AVERAGE('STUDENTS GRADE'!C5,'STUDENTS GRADE'!D5,'STUDENTS GRADE'!E5) -> 58.333333 | H35: B2:B50 | I35: {=INDIRECT("B35")} -> 107
B36: =SUM('STUDENTS GRADE'!$C$2+'STUDENTS GRADE'!E6) -> 145 | C36: =AVERAGE('STUDENTS GRADE'!C6,'STUDENTS GRADE'!D6,'STUDENTS GRADE'!E6) -> 75.333333
B37: =SUM('STUDENTS GRADE'!$C$2+'STUDENTS GRADE'!E7) -> 126 | C37: =AVERAGE('STUDENTS GRADE'!C7,'STUDENTS GRADE'!D7,'STUDENTS GRADE'!E7) -> 71.666667
B38: =SUM('STUDENTS GRADE'!$C$2+'STUDENTS GRADE'!E8) -> 139 | C38: =AVERAGE('STUDENTS GRADE'!C8,'STUDENTS GRADE'!D8,'STUDENTS GRADE'!E8) -> 66.666667 | G38: 46 | H38: OFFSET CREATE DYNAMICALLY RANGES FOR SALES TRENDS
B39: =SUM('STUDENTS GRADE'!$C$2+'STUDENTS GRADE'!E9) -> 125 | C39: =AVERAGE('STUDENTS GRADE'!C9,'STUDENTS GRADE'!D9,'STUDENTS GRADE'!E9) -> 75 | H39: =SUM(OFFSET('SALES DATA'!E2,0,0,5,1)) -> 96800
B40: =SUM('STUDENTS GRADE'!$C$2+'STUDENTS GRADE'!E10) -> 117 | C40: =AVERAGE('STUDENTS GRADE'!C10,'STUDENTS GRADE'!D10,'STUDENTS GRADE'!E10) -> 57.333333
B41: =SUM('STUDENTS GRADE'!$C$2+'STUDENTS GRADE'!E11) -> 119 | C41: =AVERAGE('STUDENTS GRADE'!C11,'STUDENTS GRADE'!D11,'STUDENTS GRADE'!E11) -> 70
...

Sheet NEW TABLE
A1: ID | B1: Full Name | C1: DOB | D1: Salary | E1: joining date | F1: date
A2: 1 | B2: Harsh Joshi | C2: 38214 | D2: 50164.451 | E2: 45919 | F2: 45648
A3: 2 | B3: Kunj Mistry | C3: 37719 | D3: 45846.651 | E3: 46077 | F3: 45768
A4: 3 | B4: Ahmed Bheshaniya | C4: 38464 | D4: 49527.541 | E4: 45770 | F4: 45657
A5: 4 | B5: Shrey Patel | C5: 38941 | D5: 46072.251 | E5: 45972 | F5: 45607
A6: 5 | B6: SAHIL PATHAN | C6: 36544 | D6: 54451.456 | E6: 45712 | F6: 45375
